Workbook

Sheet Rozdělení rolí
A1: Rozdělení projektu SI2 – telemedicínský systém pro mladé dospělé (18–40) s hypertenzí – vliv soli a energetických nápojů
A2: Člen týmu (doplňte jméno): | B2: Maky | C2: Sabi | D2: Ema | E2: Domi (možná převezme Sabi – upřesnit)
A4: Oblast | B4: 1 – Pacientská část | C4: 2 – Webový portál | D4: 3 – WEB API + databáze | E4: 4 – Integrátor NIS (FHIR)
A5: Blok systému | B5: Tlakoměr s Bluetooth + pacientská aplikace (mobil), sledování fyzické aktivity, rychlý záznam soli a energetických nápojů | C5: Portál pro pacienty a lékaře, role a oprávnění, graf tlak × životospráva | D5: Zabezpečené API, zpracování dat, autentizace | E5: Synchronizace s NIS, nastavení periody, mailové notifikace
A6: Use case diagram | B6: Pacientská aplikace | C6: Webový portál | D6: WEB API | E6: Integrátor
A7: Stavové diagramy (min. 5 celkem) | B7: 2: připojení senzoru (párování/BLE); měření a odeslání dat vč. offline režimu | C7: 1: životní cyklus upozornění/alertu pro lékaře | D7: 1: zpracování přijatého záznamu (validace → uložení → chyba) nebo přihlášení/token | E7: 1: synchronizace s NIS (čeká → synchronizuje → chyba spojení → notifikace)
A8: Návrh databáze | B8: Dodá požadavky na data | C8: Dodá požadavky na data | D8: Vlastní ER návrh (min. 6 tabulek × 4 sloupce) | E8: Dodá mapování na FHIR zdroje
A9: Návrh GUI | B9: Mobilní aplikace | C9: Webový portál | D9: – | E9: Případně obrazovka nastavení integrátoru
A10: Průřezová kapitola | B10: Údržba + distribuce updatů (store, OTA updaty firmwaru tlakoměru) | C10: Testování (postup, typy testů, testy při nasazení) | D10: Implementace (technologie, softwarový proces, verzovací systém, build server) | E10: Úvod (problém, úvod do problematiky, přehled současných řešení) + Nasazení (popis, požadavky na prostředí)
A11: Slidy do prezentace | B11: 2–3 slidy ke svému bloku | C11: 2–3 slidy ke svému bloku | D11: 2–3 slidy ke svému bloku | E11: 2–3 slidy ke svému bloku
A13: Proč je to vyrovnané:
A14: Role 3 má nejtěžší technický návrh (API + DB), proto jen jednu průřezovou kapitolu. Role 4 má technicky nejmenší blok, proto bere Úvod i Nasazení. Role 1 má dva stavové diagramy (senzor i aplikace). Cíl: cca 5 stran z 20 na osobu.

Sheet Rozhodnutí
A1: Rozhodnutí a otázky na vyučující
A2: Konzultující: Jiří Trnka, Sarrah. Hlavní je umět systém odprezentovat a rozumět mu. Otevřené otázky se zeptejte na další konzultaci a doplňte odpověď.
A4: # | B4: Otázka | C4: Odpověď vyučujících | D4: Naše rozhodnutí / výchozí volba | E4: Stav
A5: 1 | B5: Use case diagramy – minima | C5: V každém ze 4 diagramů min. 2 aktéři × 4 use casy | D5: 4 samostatné diagramy, každý splní minima sám | E5: Vyřešeno
A6: 2 | B6: Stavové diagramy – minimum 5 | C6: Pro celý tým | D6: Plánujeme 6 (role 1: 2, ostatní po 1) | E6: Vyřešeno
A7: 3 | B7: Choroba | C7: Víc týmů smí mít stejnou | D7: Hypertenze, nahlášeno 8.10. | E7: Vyřešeno
A8: 4 | B8: Cílová skupina a zaměření | C8: — | D8: Mladí dospělí 18–40 let; vliv soli a energetických nápojů (ruční rychlý záznam); děti a těhotné vyloučeny | E8: Rozhodnuto týmem
A9: 5 | B9: Termíny | C9: Nahlášení choroby 8.10., zápočet 6.1.2027 | D9: Harmonogram upraven | E9: Vyřešeno
A10: 6 | B10: Diagramy v rozsahu 20 stran / přílohy | C10: Asi ano | D10: Velké diagramy do příloh, v textu zmenšené | E10: Vyřešeno
A11: 7 | B11: Odevzdání | C11: Vše na GitHub; soubory z OneDrive nahrát na konci | D11: Úkol #32 | E11: Vyřešeno
A12: 8 | B12: Nástroj na diagramy | C12: draw.io | D12: Společná šablona stylu v /spolecne | E12: Vyřešeno
A13: 9 | B13: Technologie v návrhu | C13: Snad ano – návrh nezávislý, technologie až v Implementaci | D13: Držíme se toho; při konzultaci potvrdit | E13: Vyřešeno
A14: 10 | B14: Přehled současných řešení | C14: Ta důležitá | D14: 3–5 hlavních řešení v tabulce | E14: Vyřešeno
A15: 11 | B15: Pacientská aplikace mobil/PC | C15: Volba je na nás | D15: Mobilní aplikace | E15: Vyřešeno
A16: 12 | B16: Co na konzultaci 12.11. | C16: Asi diagramy | D16: Všechny diagramy hotové do 11.11. | E16: Vyřešeno
... A30: 26 | B30: Doba eskalace urgentního alertu | C30: — | D30: 2 h v ordinační době, mimo ni ihned zástupci; nastavuje administrátor | E30: Rozhodnuto týmem?

Sheet Úkoly
A1: Úkoly – sledování postupu
A2: Legenda: žlutá políčka (Stav, Poznámka) vyplňujte průběžně. Stav vyberte ze seznamu: Nezahájeno / Rozpracováno / Hotovo.
A4: # | B4: Úkol | C4: Kapitola dokumentu | D4: Odpovídá | E4: Termín | F4: Stav | G4: Poznámka | H4: Kroky hotovo
A5: 1 | B5: Výběr chronické choroby a nahlášení | C5: — | D5: Společně | E5: 46303 | F5: Rozpracováno | G5: Chybí krok 1.4 – zdůvodnění volby hypertenze do Úvodu (čeká na roli 4). | H5: =COUNTIFS('Osnova kroků'!$A$5:$A$171,A5,'Osnova kroků'!$F$5:$F$171,"Hotovo")&" / "&COUNTIF('Osnova kroků'!$A$5:$A$171,A5)
A6: 2 | B6: Analýza požadavků (funkční i nefunkční) | C6: Požadavky | D6: Společně | E6: 46316 | F6: Rozpracováno | G6: Spojeno do spolecny/Pozadavky_spolecne.xlsx (46 FP + 17 NFP, MoSCoW). Čeká na odsouhlasení vlastníky bloků do 1. 11., pak kapitola (Sabi). | H6: =COUNTIFS('Osnova kroků'!$A$5:$A$171,A6,'Osnova kroků'!$F$5:$F$171,"Hotovo")&" / "&COUNTIF('Osnova kroků'!$A$5:$A$171,A6)
A7: 3 | B7: Seznam aktérů a hrubé rozhraní mezi bloky | C7: Design architektury | D7: Společně | E7: 46309 | F7: Rozpracováno | G7: Aktéři jsou v UC diagramech, tok dat v Maky/02-architektura a komponenty v Maky/04. Chybí společné odsouhlasení a role 4. | H7: =COUNTIFS('Osnova kroků'!$A$5:$A$171,A7,'Osnova kroků'!$F$5:$F$171,"Hotovo")&" / "&COUNTIF('Osnova kroků'!$A$5:$A$171,A7)
A8: 4 | B8: Component diagram celého systému (kreslí role 3, odsouhlasí všichni) | C8: Design architektury | D8: Společně | E8: 46337 | F8: Nezahájeno | G8: Zatím neexistuje. Maky/04-komponenty-mobil lze použít jako výchozí bod (už ukazuje celý řetězec až po NIS). | H8: =COUNTIFS('Osnova kroků'!$A$5:$A$171,A8,'Osnova kroků'!$F$5:$F$171,"Hotovo")&" / "&COUNTIF('Osnova kroků'!$A$5:$A$171,A8)
A9: 5 | B9: Dohoda rozhraní: aplikace→API, portál↔API, integrátor→DB | C9: Design architektury | D9: Společně | E9: 46330 | F9: Rozpracováno | G9: Aplikace→API sedí (stejný JSON u Maky i Emy ✓), portál↔API sedí s tabulkou Sabi ✓. Chybí: ID zařízení a nepravidelný rytmus v JSON, integrátor→DB s rolí 4, formální odsouhlasení. | H9: =COUNTIFS('Osnova kroků'!$A$5:$A$171,A9,'Osnova kroků'!$F$5:$F$171,"Hotovo")&" / "&COUNTIF('Osnova kroků'!$A$5:$A$171,A9)
A10: 6 | B10: Sjednocení bezpečnosti a GDPR (šifrování, autentizace, role) | C10: Design architektury | D10: Společně | E10: 46323 | F10: Rozpracováno | G10: Bezpečnost je rozepsaná v Ema/Implementace §4 a Maky NFR; chybí společná podkapitola a rozhodnutí o retenci dat (GDPR). | H10: =COUNTIFS('Osnova kroků'!$A$5:$A$171,A10,'Osnova kroků'!$F$5:$F$171,"Hotovo")&" / "&COUNTIF('Osnova kroků'!$A$5:$A$171,A10)
A11: 7 | B11: Use case diagram – pacientská aplikace | C11: Požadavky | D11: 1 – Pacientská část | E11: 46323 | F11: Rozpracováno | G11: V .drawio má Tlakoměr i WEB API jen 2 use casy (zadání chce min. 4 na aktéra; v .mmd jich tlakoměr má 4 – sjednotit). Aktéři jsou obdélníky, ne UML panáčci. Šipky do „Synchronizovat data“ bez «include». Chybí UC „Číst doporučení lékaře“ (počítá s ním portál i API). | H11: =COUNTIFS('Osnova kroků'!$A$5:$A$171,A11,'Osnova kroků'!$F$5:$F$171,"Hotovo")&" / "&COUNTIF('Osnova kroků'!$A$5:$A$171,A11)
A12: 8 | B12: Stavový diagram – připojení senzoru (párování/BLE) | C12: Design architektury | D12: 1 – Pacientská část | E12: 46330 | F12: Rozpracováno | G12: Obsah OK (7 stavů). Chybí počáteční (a případně koncový) stav – černé kolečko – a odstavec popisu. | H12: =COUNTIFS('Osnova kroků'!$A$5:$A$171,A12,'Osnova kroků'!$F$5:$F$171,"Hotovo")&" / "&COUNTIF('Osnova kroků'!$A$5:$A$171,A12)
A13: 9 | B13: Stavový diagram – měření a odeslání dat vč. offline | C13: Design architektury | D13: 1 – Pacientská část | E13: 46330 | F13: Rozpracováno | G13: Obsah OK a sedí s API (401/422/5xx, idempotence ✓). Chybí počáteční/koncový stav, stav 409 konflikt (Ema), průvodce měřením a výzva při velmi vysoké hodnotě; odstavec popisu. | H13: =COUNTIFS('Osnova kroků'!$A$5:$A$171,A13,'Osnova kroků'!$F$5:$F$171,"Hotovo")&" / "&COUNTIF('Osnova kroků'!$A$5:$A$171,A13)
A14: 10 | B14: Popis pacientské části v component diagramu | C14: Design architektury | D14: 1 – Pacientská část | E14: 46337 | F14: Rozpracováno | G14: Dobrý popis (02-architektura, 04-komponenty), sedí s API i portálem. Doplnit moduly průvodce měřením a připomínky; jednotky soli zatím neschválené. | H14: =COUNTIFS('Osnova kroků'!$A$5:$A$171,A14,'Osnova kroků'!$F$5:$F$171,"Hotovo")&" / "&COUNTIF('Osnova kroků'!$A$5:$A$171,A14)
A15: 11 | B15: Návrh GUI – mobilní aplikace | C15: Design architektury | D15: 1 – Pacientská část | E15: 46351 | F15: Rozpracováno | G15: Zatím textový wireframe jedné obrazovky. Chybí obrazovky doporučení lékaře, průvodce měřením, připomínky, souhrn; nakreslit v draw.io/Figma (termín 25.11.). | H15: =COUNTIFS('Osnova kroků'!$A$5:$A$171,A15,'Osnova kroků'!$F$5:$F$171,"Hotovo")&" / "&COUNTIF('Osnova kroků'!$A$5:$A$171,A15)
A16: 12 | B16: Kapitola Údržba + distribuce updatů | C16: Údržba | D16: 1 – Pacientská část | E16: 46358 | F16: Rozpracováno | G16: Text existuje (store, OTA, firmware ✓), ale je krátký (~½ strany). Doplnit typy údržby a monitoring; cíl 1–1,5 strany. | H16: =COUNTIFS('Osnova kroků'!$A$5:$A$171,A16,'Osnova kroků'!$F$5:$F$171,"Hotovo")&" / "&COUNTIF('Osnova kroků'!$A$5:$A$171,A16)
... A31: 27 | B31: Kapitola Nasazení (popis, požadavky na prostředí) | C31: Nasazení | D31: 4 – Integrátor NIS (FHIR) | E31: 46358 | F31: Nezahájeno | G31: Role 4. | H31: =COUNTIFS('Osnova kroků'!$A$5:$A$171,A31,'Osnova kroků'!$F$5:$F$171,"Hotovo")&" / "&COUNTIF('Osnova kroků'!$A$5:$A$171,A31)
A32: 28 | B32: Zhodnocení systému a výhody oproti ostatním | C32: Zhodnocení | D32: Společně | E32: 46358 | F32: Nezahájeno | H32: =COUNTIFS('Osnova kroků'!$A$5:$A$171,A32,'Osnova kroků'!$F$5:$F$171,"Hotovo")&" / "&COUNTIF('Osnova kroků'!$A$5:$A$171,A32)
A33: 29 | B33: Výkaz práce členů v % | C33: Výkaz práce | D33: Společně | E33: 46365 | F33: Nezahájeno | H33: =COUNTIFS('Osnova kroků'!$A$5:$A$171,A33,'Osnova kroků'!$F$5:$F$171,"Hotovo")&" / "&COUNTIF('Osnova kroků'!$A$5:$A$171,A33)
A34: 30 | B34: Prezentace (10–15 slidů), každý 2–3 slidy | C34: Prezentace | D34: Společně | E34: 46365 | F34: Nezahájeno | H34: =COUNTIFS('Osnova kroků'!$A$5:$A$171,A34,'Osnova kroků'!$F$5:$F$171,"Hotovo")&" / "&COUNTIF('Osnova kroků'!$A$5:$A$171,A34)
A35: 31 | B35: Finální redakce: jednotný styl diagramů a terminologie | C35: Celý dokument | D35: Společně | E35: 46365 | F35: Nezahájeno | H35: =COUNTIFS('Osnova kroků'!$A$5:$A$171,A35,'Osnova kroků'!$F$5:$F$171,"Hotovo")&" / "&COUNTIF('Osnova kroků'!$A$5:$A$171,A35)
A36: 32 | B36: GitHub: průběžné používání a finální odevzdání (hodnotí se) | C36: Odevzdání | D36: Společně | E36: 46372 | F36: Rozpracováno | G36: Commity probíhají, ale zprávy „Add files via upload“ nic neříkají – psát popisné (hodnotí se). Složky spolecny a Domi prázdné. | H36: =COUNTIFS('Osnova kroků'!$A$5:$A$171,A36,'Osnova kroků'!$F$5:$F$171,"Hotovo")&" / "&COUNTIF('Osnova kroků'!$A$5:$A$171,A36)
A37: 33 | B37: Porozumění celku: každý umí vysvětlit svůj blok i tok dat od tlakoměru do NIS | C37: Prezentace / obhajoba | D37: Společně | E37: 46365 | F37: Nezahájeno | H37: =COUNTIFS('Osnova kroků'!$A$5:$A$171,A37,'Osnova kroků'!$F$5:$F$171,"Hotovo")&" / "&COUNTIF('Osnova kroků'!$A$5:$A$171,A37)

Sheet Osnova kroků
A1: Podrobná osnova kroků ke každému úkolu
A2: Legenda: žlutá políčka (Stav, Poznámka) vyplňujte průběžně. Postup za úkol se počítá v listu Úkoly (sloupec Kroky hotovo).
A4: Úkol # | B4: Úkol | C4: Krok | D4: Popis kroku | E4: Odpovídá | F4: Stav | G4: Poznámka
A5: 1 | B5: Výběr chronické choroby a nahlášení | C5: 1.1 | D5: Porovnat 4 choroby podle senzorů, měřených hodnot a vhodnosti sledování aktivity. | E5: =INDEX(Úkoly!$D$5:$D$37,MATCH(A5,Úkoly!$A$5:$A$37,0)) | F5: Hotovo
A6: 1 | C6: 1.2 | D6: Zvolena HYPERTENZE (tlakoměr s Bluetooth: systolický a diastolický tlak, puls; fyzická aktivita prokazatelně snižuje tlak). | E6: =INDEX(Úkoly!$D$5:$D$37,MATCH(A6,Úkoly!$A$5:$A$37,0)) | F6: Hotovo
A7: 1 | C7: 1.3 | D7: Nahlášeno vyučujícímu 8.10. | E7: =INDEX(Úkoly!$D$5:$D$37,MATCH(A7,Úkoly!$A$5:$A$37,0)) | F7: Hotovo
A8: 1 | C8: 1.4 | D8: Zapsat 1–2 věty zdůvodnění volby do Úvodu. | E8: =INDEX(Úkoly!$D$5:$D$37,MATCH(A8,Úkoly!$A$5:$A$37,0)) | F8: Nezahájeno
A9: 2 | B9: Analýza požadavků (funkční i nefunkční) | C9: 2.1 | D9: Cílová skupina: mladí dospělí 18–40 let s léčenou hypertenzí, u nichž hraje roli životní styl (sůl, energetické nápoje, málo pohybu). Vyloučit děti/dospívající a těhotné. | E9: =INDEX(Úkoly!$D$5:$D$37,MATCH(A9,Úkoly!$A$5:$A$37,0)) | F9: Hotovo
A10: 2 | C10: 2.2 | D10: Vytvořit 2–3 persony, např. student 22 let (energetické nápoje při zkouškách), IT pracovník 34 let (sedavá práce, slané jídlo), praktický lékař. | E10: =INDEX(Úkoly!$D$5:$D$37,MATCH(A10,Úkoly!$A$5:$A$37,0)) | F10: Rozpracováno
A11: 2 | C11: 2.3 | D11: Brainstorming funkčních požadavků po blocích; každý přinese 5–10 požadavků. Nezapomenout na rychlý záznam soli a energetických nápojů a jeho zobrazení lékaři. | E11: =INDEX(Úkoly!$D$5:$D$37,MATCH(A11,Úkoly!$A$5:$A$37,0)) | F11: Hotovo | G11: Ve společné tabulce; čeká na potvrzení
A12: 2 | C12: 2.4 | D12: Nefunkční požadavky: bezpečnost, GDPR, dostupnost, offline režim, rychlost zadání (záznam do 3 klepnutí), motivace k pravidelnému používání. | E12: =INDEX(Úkoly!$D$5:$D$37,MATCH(A12,Úkoly!$A$5:$A$37,0)) | F12: Hotovo | G12: Ve společné tabulce; čeká na potvrzení
A13: 2 | C13: 2.5 | D13: Očíslovat požadavky (FP-01…, NFP-01…) a přiřadit prioritu MoSCoW; záznam životosprávy jako Must, motivační prvky jako Could. | E13: =INDEX(Úkoly!$D$5:$D$37,MATCH(A13,Úkoly!$A$5:$A$37,0)) | F13: Rozpracováno | G13: Očíslováno, MoSCoW navrženo – odsouhlasit
A14: 2 | C14: 2.6 | D14: Projít s cvičícími a sepsat kapitolu „Analýza požadavků“ (tabulka + úvodní text). | E14: =INDEX(Úkoly!$D$5:$D$37,MATCH(A14,Úkoly!$A$5:$A$37,0)) | F14: Nezahájeno
A15: 3 | B15: Seznam aktérů a hrubé rozhraní mezi bloky | C15: 3.1 | D15: Pro každého aktéra napsat 1 větu: kdo to je a co od systému chce. | E15: =INDEX(Úkoly!$D$5:$D$37,MATCH(A15,Úkoly!$A$5:$A$37,0)) | F15: Rozpracováno
A16: 3 | C16: 3.2 | D16: Určit, kteří aktéři komunikují s kterým blokem (matice aktér × blok). | E16: =INDEX(Úkoly!$D$5:$D$37,MATCH(A16,Úkoly!$A$5:$A$37,0)) | F16: Nezahájeno
A17: 3 | C17: 3.3 | D17: Nakreslit hrubé schéma: senzor → aplikace → API → DB ← portál; DB ← integrátor → NIS. | E17: =INDEX(Úkoly!$D$5:$D$37,MATCH(A17,Úkoly!$A$5:$A$37,0)) | F17: Hotovo
A18: 3 | C18: 3.4 | D18: Ke každé šipce napsat, jaká data tečou a jakým směrem. | E18: =INDEX(Úkoly!$D$5:$D$37,MATCH(A18,Úkoly!$A$5:$A$37,0)) | F18: Rozpracováno
A19: 3 | C19: 3.5 | D19: Odsouhlasit schéma v týmu; slouží jako podklad pro component diagram a use case diagramy. | E19: =INDEX(Úkoly!$D$5:$D$37,MATCH(A19,Úkoly!$A$5:$A$37,0)) | F19: Nezahájeno
A20: 4 | B20: Component diagram celého systému (kreslí role 3, odsouhlasí všichni) | C20: 4.1 | D20: Nástroj: draw.io (určeno vyučujícím). Vytvořit sdílenou šablonu stylu (barvy, písmo, velikost) ve složce /spolecne. | E20: =INDEX(Úkoly!$D$5:$D$37,MATCH(A20,Úkoly!$A$5:$A$37,0)) | F20: Nezahájeno
A21: 4 | C21: 4.2 | D21: Zakreslit komponenty: tlakoměr (BLE), zdroj aktivity (telefon / náramek), pacientská aplikace, WEB API, databáze, webový portál, integrátor NIS, NIS, mailový server. | E21: =INDEX(Úkoly!$D$5:$D$37,MATCH(A21,Úkoly!$A$5:$A$37,0)) | F21: Nezahájeno
A22: 4 | C22: 4.3 | D22: Přidat rozhraní (provided/required) a propojení; u každého spoje uvést protokol obecně (BLE, HTTPS/REST, HL7 FHIR, SMTP) – návrh nemá záviset na konkrétní technologii. | E22: =INDEX(Úkoly!$D$5:$D$37,MATCH(A22,Úkoly!$A$5:$A$37,0)) | F22: Nezahájeno
A23: 4 | C23: 4.4 | D23: Vyznačit, že integrátor přistupuje do DB napřímo, bez WEB API (požadavek zadání). | E23: =INDEX(Úkoly!$D$5:$D$37,MATCH(A23,Úkoly!$A$5:$A$37,0)) | F23: Nezahájeno
A24: 4 | C24: 4.5 | D24: Každý vlastník bloku zkontroluje svou část diagramu. | E24: =INDEX(Úkoly!$D$5:$D$37,MATCH(A24,Úkoly!$A$5:$A$37,0)) | F24: Nezahájeno
A25: 4 | C25: 4.6 | D25: Sepsat popis propojení celého systému (úvodní odstavec kapitoly Design architektury). | E25: =INDEX(Úkoly!$D$5:$D$37,MATCH(A25,Úkoly!$A$5:$A$37,0)) | F25: Nezahájeno
A26: 5 | B26: Dohoda rozhraní: aplikace→API, portál↔API, integrátor→DB | C26: 5.1 | D26: Aplikace → API: definovat zprávu s měřením (ID pacienta, typ měření, hodnota, jednotka, čas, ID zařízení). | E26: =INDEX(Úkoly!$D$5:$D$37,MATCH(A26,Úkoly!$A$5:$A$37,0)) | F26: Rozpracováno | G26: Chybí ID zařízení a nepravidelný rytmus.
A27: 5 | C27: 5.2 | D27: Portál ↔ API: sepsat seznam operací (čtení měření, editace záznamu, správa uživatelů, alerty, poznámky lékaře). | E27: =INDEX(Úkoly!$D$5:$D$37,MATCH(A27,Úkoly!$A$5:$A$37,0)) | F27: Hotovo
A28: 5 | C28: 5.3 | D28: Navrhnout hrubý seznam endpointů (např. POST /measurements, GET /patients/{id}/measurements, …) a návratové kódy chyb. | E28: =INDEX(Úkoly!$D$5:$D$37,MATCH(A28,Úkoly!$A$5:$A$37,0)) | F28: Hotovo
A29: 5 | C29: 5.4 | D29: Integrátor → DB: určit, které tabulky čte/zapisuje a jak pozná, co už synchronizoval (např. příznak/čas poslední synchronizace). | E29: =INDEX(Úkoly!$D$5:$D$37,MATCH(A29,Úkoly!$A$5:$A$37,0)) | F29: Rozpracováno
A30: 5 | C30: 5.5 | D30: Zapsat dohodu do sdíleného dokumentu; každá pozdější změna jen po domluvě s dotčenými vlastníky. | E30: =INDEX(Úkoly!$D$5:$D$37,MATCH(A30,Úkoly!$A$5:$A$37,0)) | F30: Nezahájeno
A31: 6 | B31: Sjednocení bezpečnosti a GDPR (šifrování, autentizace, role) | C31: 6.1 | D31: Určit způsob autentizace (např. OAuth2/OpenID Connect, tokeny) a autorizace (role pacient / lékař / admin). | E31: =INDEX(Úkoly!$D$5:$D$37,MATCH(A31,Úkoly!$A$5:$A$37,0)) | F31: Rozpracováno
A32: 6 | C32: 6.2 | D32: Popsat šifrování: přenos (TLS), uložení (šifrování citlivých dat v DB), párování senzoru. | E32: =INDEX(Úkoly!$D$5:$D$37,MATCH(A32,Úkoly!$A$5:$A$37,0)) | F32: Rozpracováno
A33: 6 | C33: 6.3 | D33: GDPR: jaká osobní/zdravotní data se zpracovávají, souhlas pacienta, právo na výmaz a export, doba uchování. | E33: =INDEX(Úkoly!$D$5:$D$37,MATCH(A33,Úkoly!$A$5:$A$37,0)) | F33: Rozpracováno
A34: 6 | C34: 6.4 | D34: Logování a audit přístupů ke zdravotním datům (kdo, kdy, co viděl/změnil). | E34: =INDEX(Úkoly!$D$5:$D$37,MATCH(A34,Úkoly!$A$5:$A$37,0)) | F34: Hotovo
A35: 6 | C35: 6.5 | D35: Sepsat krátkou podkapitolu Bezpečnost a každý ji zmíní ve svém bloku. | E35: =INDEX(Úkoly!$D$5:$D$37,MATCH(A35,Úkoly!$A$5:$A$37,0)) | F35: Nezahájeno
A36: 7 | B36: Use case diagram – pacientská aplikace | C36: 7.1 | D36: Aktéři (min. 2, každý min. 4 use casy): Pacient, Tlakoměr. | E36: =INDEX(Úkoly!$D$5:$D$37,MATCH(A36,Úkoly!$A$5:$A$37,0)) | F36: Rozpracováno | G36: Tlakoměr i WEB API mají v .drawio jen 2 UC.
A37: 7 | C37: 7.2 | D37: Pacient: přihlásit se; spárovat tlakoměr; provést měření podle průvodce; prohlížet historii tlaku a graf; rychle zaznamenat energetický nápoj; rychle zaznamenat slané jídlo; nastavit připomínky; zobrazit doporučení lékaře. | E37: =INDEX(Úkoly!$D$5:$D$37,MATCH(A37,Úkoly!$A$5:$A$37,0)) | F37: Rozpracováno
A38: 7 | C38: 7.3 | D38: Tlakoměr: odeslat naměřené hodnoty (SYS, DIA, puls, čas); oznámit nepravidelný srdeční rytmus; oznámit chybu měření; oznámit stav baterie. | E38: =INDEX(Úkoly!$D$5:$D$37,MATCH(A38,Úkoly!$A$5:$A$37,0)) | F38: Rozpracováno
A39: 7 | C39: 7.4 | D39: Doplnit vztahy include/extend (např. „Provést měření“ include „Odeslat data na server“; „Zobrazit graf“ extend „Zobrazit záznamy životosprávy“). | E39: =INDEX(Úkoly!$D$5:$D$37,MATCH(A39,Úkoly!$A$5:$A$37,0)) | F39: Rozpracováno
A40: 7 | C40: 7.5 | D40: Nakreslit v draw.io ve společném stylu. | E40: =INDEX(Úkoly!$D$5:$D$37,MATCH(A40,Úkoly!$A$5:$A$37,0)) | F40: Hotovo
A41: 7 | C41: 7.6 | D41: Ke 2–3 klíčovým use casům napsat krátký scénář (měření, rychlý záznam energetického nápoje). | E41: =INDEX(Úkoly!$D$5:$D$37,MATCH(A41,Úkoly!$A$5:$A$37,0)) | F41: Hotovo
...

Sheet Přehled
A1: Přehled postupu podle odpovědnosti
A3: Odpovídá | B3: Úkolů celkem | C3: Hotovo | D3: Rozpracováno | E3: Hotovo %
A4: 1 – Pacientská část | B4: =COUNTIF(Úkoly!$D$5:$D$37,A4) | C4: =COUNTIFS(Úkoly!$D$5:$D$37,A4,Úkoly!$F$5:$F$37,"Hotovo") | D4: =COUNTIFS(Úkoly!$D$5:$D$37,A4,Úkoly!$F$5:$F$37,"Rozpracováno") | E4: =IF(B4=0,0,C4/B4)
A5: 2 – Webový portál | B5: =COUNTIF(Úkoly!$D$5:$D$37,A5) | C5: =COUNTIFS(Úkoly!$D$5:$D$37,A5,Úkoly!$F$5:$F$37,"Hotovo") | D5: =COUNTIFS(Úkoly!$D$5:$D$37,A5,Úkoly!$F$5:$F$37,"Rozpracováno") | E5: =IF(B5=0,0,C5/B5)
A6: 3 – WEB API + databáze | B6: =COUNTIF(Úkoly!$D$5:$D$37,A6) | C6: =COUNTIFS(Úkoly!$D$5:$D$37,A6,Úkoly!$F$5:$F$37,"Hotovo") | D6: =COUNTIFS(Úkoly!$D$5:$D$37,A6,Úkoly!$F$5:$F$37,"Rozpracováno") | E6: =IF(B6=0,0,C6/B6)
A7: 4 – Integrátor NIS (FHIR) | B7: =COUNTIF(Úkoly!$D$5:$D$37,A7) | C7: =COUNTIFS(Úkoly!$D$5:$D$37,A7,Úkoly!$F$5:$F$37,"Hotovo") | D7: =COUNTIFS(Úkoly!$D$5:$D$37,A7,Úkoly!$F$5:$F$37,"Rozpracováno") | E7: =IF(B7=0,0,C7/B7)
A8: Společně | B8: =COUNTIF(Úkoly!$D$5:$D$37,A8) | C8: =COUNTIFS(Úkoly!$D$5:$D$37,A8,Úkoly!$F$5:$F$37,"Hotovo") | D8: =COUNTIFS(Úkoly!$D$5:$D$37,A8,Úkoly!$F$5:$F$37,"Rozpracováno") | E8: =IF(B8=0,0,C8/B8)
A9: Celkem | B9: =SUM(B4:B8) | C9: =SUM(C4:C8) | D9: =SUM(D4:D8) | E9: =IF(B9=0,0,C9/B9)

Sheet Harmonogram
A1: Týdenní harmonogram (termín = středa večer, ve čtvrtek se na hodině kontroluje)
A2: Čísla #N odpovídají úkolům v listu Úkoly. Vše hotovo do 9.12., týden 10.–16.12. je rezerva.
A4: Týden | B4: Od | C4: Termín | D4: Konzultace / milník | E4: Společně | F4: 1 – Pacientská část | G4: 2 – Webový portál | H4: 3 – WEB API + databáze | I4: 4 – Integrátor NIS (FHIR)
A5: 1 | B5: 46303 | C5: 46309 | D5: 8.10. konzultace – sběr požadavků | E5: #1 hypertenze zvolena ✓; #3 aktéři a hrubé schéma; založit GitHub (#32), OneDrive, šablonu draw.io; začít #2 požadavky | F5: Nasbírat požadavky na aplikaci a senzor | G5: Nasbírat požadavky na portál a role | H5: Nasbírat požadavky na API a data | I5: Nasbírat požadavky na integrátor; rešerše současných řešení
A6: 2 | B6: 46310 | C6: 46316 | E6: #2 dokončit analýzu požadavků; začít #5 dohodu rozhraní | F6: Začít #7 UC pacientská aplikace | G6: Začít #13 UC portál | H6: Začít #18 UC API; sbírat požadavky na data pro DB | I6: Začít #23 UC integrátor; nastudovat FHIR (#25)
A7: 3 | B7: 46317 | C7: 46323 | E7: #6 bezpečnost a GDPR | F7: #7 UC hotovo | G7: #13 UC hotovo | H7: #18 UC hotovo; první návrh tabulek (#20) | I7: #23 UC hotovo; mapování na FHIR zdroje (#25)
A8: 4 | B8: 46324 | C8: 46330 | E8: #5 dohoda rozhraní finální; role 3 kreslí návrh component diagramu (#4) | F8: #8 + #9 stavové diagramy | G8: #14 stavový diagram alertu | H8: #19 stavový diagram; #20 ER diagram hotový | I8: #24 stavový diagram synchronizace
A9: 5 | B9: 46331 | C9: 46337 | D9: Propojení: vše zkontrolovat před konzultací | E9: #4 component diagram finální; všichni si navzájem zkontrolují diagramy (soulad UC ↔ DB ↔ rozhraní) | F9: #10 popis pacientské části | G9: #15 popis portálu a oprávnění | H9: #21 popis API a DB | I9: #25 popis integrátoru a FHIR
A10: 6 | B10: 46338 | C10: 46344 | D10: 12.11. konzultace – architektura a rozdělení | E10: Zapracovat připomínky z konzultace; zeptat se na otevřené otázky z listu Rozhodnutí | F10: Wireframy mobilní aplikace (#11) | G10: Wireframy portálu (#16) | H10: Začít #22 Implementace | I10: #26 Úvod hotový
A11: 7 | B11: 46345 | C11: 46351 | E11: Sjednotit vzhled GUI (aplikace × portál) | F11: #11 GUI aplikace hotové; začít #12 Údržba | G11: #16 GUI portálu hotové; začít #17 Testování (sebrat scénáře od ostatních) | H11: #22 Implementace – koncept | I11: Začít #27 Nasazení
A12: 8 | B12: 46352 | C12: 46358 | D12: 26.11. konzultace – kontrola postupu | E12: Zapracovat připomínky; #28 Zhodnocení; osnova prezentace (#30) | F12: #12 Údržba hotová | G12: #17 Testování hotové | H12: #22 Implementace hotová | I12: #27 Nasazení hotové
A13: 9 | B13: 46359 | C13: 46365 | D13: DOKONČENO: dokument i prezentace | E13: #31 spojit dokument, kontrola minimálních požadavků, jednotný styl, obsah a zdroje; #30 slidy; #29 výkaz práce | F13: 2–3 slidy + korektura cizí kapitoly | G13: 2–3 slidy + korektura cizí kapitoly | H13: 2–3 slidy + korektura cizí kapitoly | I13: 2–3 slidy + korektura cizí kapitoly
A14: 10 | B14: 46366 | C14: 46372 | D14: REZERVA | E14: Jen opravy a nácvik prezentace (cca 15 min s časomírou), otázky komise navzájem (#33); nahrát finální soubory z OneDrive na GitHub, přidat vyučující, tag v-odevzdani (#32) | F14: Rezerva | G14: Rezerva | H14: Rezerva | I14: Rezerva
A15: – | B15: 46373 | C15: 46373 | D15: 17.12. prezentace a odevzdání | E15: Prezentace a obhajoba
A16: – | B16: 46374 | C16: 46393 | D16: 6.1. zápočet | E16: Zapracovat připomínky komise
